<?xml version="1.0" ?>
<sdf version='1.6'>
  <model name='wx200'>
    <link name='wx200/base_link'>
      <pose frame=''>0 0 0 0 -0 0</pose>
      <inertial>
        <pose frame=''>-0.038175 0.000648 0.019346 0 -0 1.5708</pose>
        <mass>0.540142</mass>
        <inertia>
          <ixx>0.002119</ixx>
          <ixy>-1.721e-05</ixy>
          <ixz>6.389e-07</ixz>
          <iyy>0.0006925</iyy>
          <iyz>4.612e-05</iyz>
          <izz>0.002528</izz>
        </inertia>
      </inertial>
      <collision name='wx200/base_link_collision'>
        <pose frame=''>0 0 0 0 -0 1.5708</pose>
        <geometry>
          <mesh>
            <scale>0.001 0.001 0.001</scale>
            <uri>model://interbotix_xsarm_descriptions/meshes/wx200_meshes/wx200_1_base.stl</uri>
          </mesh>
        </geometry>
      </collision>
      <visual name='wx200/base_link_visual'>
        <pose frame=''>0 0 0 0 -0 1.5708</pose>
        <geometry>
          <mesh>
            <scale>0.001 0.001 0.001</scale>
            <uri>model://interbotix_xsarm_descriptions/meshes/wx200_meshes/wx200_1_base.stl</uri>
          </mesh>
        </geometry>
      </visual>
    </link>
    <link name='wx200/shoulder_link'>
      <pose frame=''>0 0 0.072 0 -0 0</pose>
      <inertial>
        <pose frame=''>2.2e-05 4.1e-05 0.006629 0 -0 1.5708</pose>
        <mass>0.480879</mass>
        <inertia>
          <ixx>0.000379</ixx>
          <ixy>2.2e-09</ixy>
          <ixz>-3.561e-07</ixz>
          <iyy>0.0005557</iyy>
          <iyz>1.2247e-06</iyz>
          <izz>0.0005889</izz>
        </inertia>
      </inertial>
      <collision name='wx200/shoulder_link_collision'>
        <pose frame=''>0 0 -0.003 0 -0 1.5708</pose>
        <geometry>
          <mesh>
            <scale>0.001 0.001 0.001</scale>
            <uri>model://interbotix_xsarm_descriptions/meshes/wx200_meshes/wx200_2_shoulder.stl</uri>
          </mesh>
        </geometry>
      </collision>
      <visual name='wx200/shoulder_link_visual'>
        <pose frame=''>0 0 -0.003 0 -0 1.5708</pose>
        <geometry>
          <mesh>
            <scale>0.001 0.001 0.001</scale>
            <uri>model://interbotix_xsarm_descriptions/meshes/wx200_meshes/wx200_2_shoulder.stl</uri>
          </mesh>
        </geometry>
      </visual>
    </link>
    <joint name='waist' type='revolute'>
      <child>wx200/shoulder_link</child>
      <parent>wx200/base_link</parent>
      <axis>
        <xyz>0 0 1</xyz>
        <limit>
          <lower>-3.14158</lower>
          <upper>3.14158</upper>
          <effort>8</effort>
          <velocity>3.14159</velocity>
        </limit>
        <dynamics>
          <damping>0</damping>
          <friction>0.1</friction>
          <spring_reference>0</spring_reference>
          <spring_stiffness>0</spring_stiffness>
        </dynamics>
        <use_parent_model_frame>0</use_parent_model_frame>
      </axis>
    </joint>
    <link name='wx200/upper_arm_link'>
      <pose frame=''>0 0 0.11065 0 -0 0</pose>
      <inertial>
        <pose frame=''>0.011971 -0.000118 0.139429 0 -0 1.5708</pose>
        <mass>0.297781</mass>
        <inertia>
          <ixx>0.00171</ixx>
          <ixy>-1.1433e-06</ixy>
          <ixz>2.1161e-06</ixz>
          <iyy>0.001631</iyy>
          <iyz>0.0002135</iyz>
          <izz>0.0001482</izz>
        </inertia>
      </inertial>
      <collision name='wx200/upper_arm_link_collision'>
        <pose frame=''>0 0 0 0 -0 1.5708</pose>
        <geometry>
          <mesh>
            <scale>0.001 0.001 0.001</scale>
            <uri>model://interbotix_xsarm_descriptions/meshes/wx200_meshes/wx200_3_upper_arm.stl</uri>
          </mesh>
        </geometry>
      </collision>
      <visual name='wx200/upper_arm_link_visual'>
        <pose frame=''>0 0 0 0 -0 1.5708</pose>
        <geometry>
          <mesh>
            <scale>0.001 0.001 0.001</scale>
            <uri>model://interbotix_xsarm_descriptions/meshes/wx200_meshes/wx200_3_upper_arm.stl</uri>
          </mesh>
        </geometry>
      </visual>
    </link>
    <joint name='shoulder' type='revolute'>
      <child>wx200/upper_arm_link</child>
      <parent>wx200/shoulder_link</parent>
      <axis>
        <xyz>0 1 0</xyz>
        <limit>
          <lower>-1.88496</lower>
          <upper>1.97222</upper>
          <effort>18</effort>
          <velocity>3.14159</velocity>
        </limit>
        <dynamics>
          <damping>0</damping>
          <friction>0.1</friction>
          <spring_reference>0</spring_reference>
          <spring_stiffness>0</spring_stiffness>
        </dynamics>
        <use_parent_model_frame>0</use_parent_model_frame>
      </axis>
    </joint>
    <link name='wx200/forearm_link'>
      <pose frame=''>0.05 0 0.31065 0 -0 0</pose>
      <inertial>
        <pose frame=''>0.121192 -0.000124 0 0 -0 1.5708</pose>
        <mass>0.283651</mass>
        <inertia>
          <ixx>0.001185</ixx>
          <ixy>-2.4317e-06</ixy>
          <ixz>0</ixz>
          <iyy>6.829e-05</iyy>
          <iyz>0</iyz>
          <izz>0.001206</izz>
        </inertia>
      </inertial>
      <collision name='wx200/forearm_link_collision'>
        <pose frame=''>0 0 0 0 -0 1.5708</pose>
        <geometry>
          <mesh>
            <scale>0.001 0.001 0.001</scale>
            <uri>model://interbotix_xsarm_descriptions/meshes/wx200_meshes/wx200_4_forearm.stl</uri>
          </mesh>
        </geometry>
      </collision>
      <visual name='wx200/forearm_link_visual'>
        <pose frame=''>0 0 0 0 -0 1.5708</pose>
        <geometry>
          <mesh>
            <scale>0.001 0.001 0.001</scale>
            <uri>model://interbotix_xsarm_descriptions/meshes/wx200_meshes/wx200_4_forearm.stl</uri>
          </mesh>
        </geometry>
      </visual>
    </link>
    <joint name='elbow' type='revolute'>
      <child>wx200/forearm_link</child>
      <parent>wx200/upper_arm_link</parent>
      <axis>
        <xyz>0 1 0</xyz>
        <limit>
          <lower>-1.88496</lower>
          <upper>1.62316</upper>
          <effort>13</effort>
          <velocity>3.14159</velocity>
        </limit>
        <dynamics>
          <damping>0</damping>
          <friction>0.1</friction>
          <spring_reference>0</spring_reference>
          <spring_stiffness>0</spring_stiffness>
        </dynamics>
        <use_parent_model_frame>0</use_parent_model_frame>
      </axis>
    </joint>
    <link name='wx200/wrist_link'>
      <pose frame=''>0.25 0 0.31065 0 -0 0</pose>
      <inertial>
        <pose frame=''>0.04236 -1.1e-05 0.010577 0 -0 1.5708</pose>
        <mass>0.084957</mass>
        <inertia>
          <ixx>3.082e-05</ixx>
          <ixy>1.91e-08</ixy>
          <ixz>2.3e-09</ixz>
          <iyy>2.822e-05</iyy>
          <iyz>2.5481e-06</iyz>
          <izz>3.152e-05</izz>
        </inertia>
      </inertial>
      <collision name='wx200/wrist_link_collision'>
        <pose frame=''>0 0 0 0 -0 1.5708</pose>
        <geometry>
          <mesh>
            <scale>0.001 0.001 0.001</scale>
            <uri>model://interbotix_xsarm_descriptions/meshes/wx200_meshes/wx200_5_wrist.stl</uri>
          </mesh>
        </geometry>
      </collision>
      <visual name='wx200/wrist_link_visual'>
        <pose frame=''>0 0 0 0 -0 1.5708</pose>
        <geometry>
          <mesh>
            <scale>0.001 0.001 0.001</scale>
            <uri>model://interbotix_xsarm_descriptions/meshes/wx200_meshes/wx200_5_wrist.stl</uri>
          </mesh>
        </geometry>
      </visual>
    </link>
    <joint name='wrist_angle' type='revolute'>
      <child>wx200/wrist_link</child>
      <parent>wx200/forearm_link</parent>
      <axis>
        <xyz>0 1 0</xyz>
        <limit>
          <lower>-1.74533</lower>
          <upper>2.14675</upper>
          <effort>5</effort>
          <velocity>3.14159</velocity>
        </limit>
        <dynamics>
          <damping>0</damping>
          <friction>0.1</friction>
          <spring_reference>0</spring_reference>
          <spring_stiffness>0</spring_stiffness>
        </dynamics>
        <use_parent_model_frame>0</use_parent_model_frame>
      </axis>
    </joint>
    <link name='wx200/gripper_link'>
      <pose frame=''>0.315 0 0.31065 0 -0 0</pose>
      <inertial>
        <pose frame=''>0.03253 0 0.009096 0 -0 1.5708</pose>
        <mass>0.110084</mass>
        <inertia>
          <ixx>0.00306151</ixx>
          <ixy>-4.36167e-10</ixy>
          <ixz>-5.26833e-10</ixz>
          <iyy>0.00304801</iyy>
          <iyz>-6.59779e-06</iyz>
          <izz>0.00307285</izz>
        </inertia>
      </inertial>
      <collision name='wx200/gripper_link_collision'>
        <pose frame=''>-0.02 0 0 0 -0 1.5708</pose>
        <geometry>
          <mesh>
            <scale>0.001 0.001 0.001</scale>
            <uri>model://interbotix_xsarm_descriptions/meshes/wx200_meshes/wx200_6_gripper.stl</uri>
          </mesh>
        </geometry>
      </collision>
      <collision name='wx200/gripper_link_fixed_joint_lump__wx200/gripper_bar_link_collision_1'>
        <pose frame=''>-0.02 0 0 0 -0 1.5708</pose>
        <geometry>
          <mesh>
            <scale>0.001 0.001 0.001</scale>
            <uri>model://interbotix_xsarm_descriptions/meshes/wx200_meshes/wx200_8_gripper_bar.stl</uri>
          </mesh>
        </geometry>
      </collision>
      <visual name='wx200/gripper_link_visual'>
        <pose frame=''>-0.02 0 0 0 -0 1.5708</pose>
        <geometry>
          <mesh>
            <scale>0.001 0.001 0.001</scale>
            <uri>model://interbotix_xsarm_descriptions/meshes/wx200_meshes/wx200_6_gripper.stl</uri>
          </mesh>
        </geometry>
      </visual>
      <visual name='wx200/gripper_link_fixed_joint_lump__wx200/gripper_bar_link_visual_1'>
        <pose frame=''>-0.02 0 0 0 -0 1.5708</pose>
        <geometry>
          <mesh>
            <scale>0.001 0.001 0.001</scale>
            <uri>model://interbotix_xsarm_descriptions/meshes/wx200_meshes/wx200_8_gripper_bar.stl</uri>
          </mesh>
        </geometry>
      </visual>
    </link>
    <joint name='wrist_rotate' type='revolute'>
      <child>wx200/gripper_link</child>
      <parent>wx200/wrist_link</parent>
      <axis>
        <xyz>1 0 0</xyz>
        <limit>
          <lower>-3.14158</lower>
          <upper>3.14158</upper>
          <effort>1</effort>
          <velocity>3.14159</velocity>
        </limit>
        <dynamics>
          <damping>0</damping>
          <friction>0.1</friction>
          <spring_reference>0</spring_reference>
          <spring_stiffness>0</spring_stiffness>
        </dynamics>
        <use_parent_model_frame>0</use_parent_model_frame>
      </axis>
    </joint>
    <link name='wx200/gripper_prop_link'>
      <pose frame=''>0.3635 0 0.31065 0 -0 0</pose>
      <inertial>
        <pose frame=''>0.000846 -2e-06 4.2e-05 0 -0 1.5708</pose>
        <mass>0.00434</mass>
        <inertia>
          <ixx>5.923e-07</ixx>
          <ixy>0</ixy>
          <ixz>3.195e-07</ixz>
          <iyy>1.1156e-06</iyy>
          <iyz>-4e-10</iyz>
          <izz>5.743e-07</izz>
        </inertia>
      </inertial>
      <collision name='wx200/gripper_prop_link_collision'>
        <pose frame=''>-0.0685 0 0 0 -0 1.5708</pose>
        <geometry>
          <mesh>
            <scale>0.001 0.001 0.001</scale>
            <uri>model://interbotix_xsarm_descriptions/meshes/wx200_meshes/wx200_7_gripper_prop.stl</uri>
          </mesh>
        </geometry>
      </collision>
      <visual name='wx200/gripper_prop_link_visual'>
        <pose frame=''>-0.0685 0 0 0 -0 1.5708</pose>
        <geometry>
          <mesh>
            <scale>0.001 0.001 0.001</scale>
            <uri>model://interbotix_xsarm_descriptions/meshes/wx200_meshes/wx200_7_gripper_prop.stl</uri>
          </mesh>
        </geometry>
      </visual>
    </link>
    <joint name='gripper' type='revolute'>
      <child>wx200/gripper_prop_link</child>
      <parent>wx200/gripper_link</parent>
      <axis>
        <xyz>1 0 0</xyz>
        <limit>
          <lower>-1e+16</lower>
          <upper>1e+16</upper>
        </limit>
        <dynamics>
          <damping>0</damping>
          <friction>0.1</friction>
          <spring_reference>0</spring_reference>
          <spring_stiffness>0</spring_stiffness>
        </dynamics>
        <use_parent_model_frame>0</use_parent_model_frame>
      </axis>
    </joint>
    <link name='wx200/left_finger_link'>
      <pose frame=''>0.381 0 0.31065 0 -0 0</pose>
      <inertial>
        <pose frame=''>0.013816 0 0 0 -0 -1.5708</pose>
        <mass>0.016246</mass>
        <inertia>
          <ixx>4.731e-06</ixx>
          <ixy>-4.56e-07</ixy>
          <ixz>0</ixz>
          <iyy>1.5506e-06</iyy>
          <iyz>0</iyz>
          <izz>3.7467e-06</izz>
        </inertia>
      </inertial>
      <collision name='wx200/left_finger_link_collision'>
        <pose frame=''>0 0.005 0 0 -0 3.14159</pose>
        <geometry>
          <mesh>
            <scale>0.001 0.001 0.001</scale>
            <uri>model://interbotix_xsarm_descriptions/meshes/wx200_meshes/wx200_9_gripper_finger.stl</uri>
          </mesh>
        </geometry>
      </collision>
      <visual name='wx200/left_finger_link_visual'>
        <pose frame=''>0 0.005 0 0 -0 3.14159</pose>
        <geometry>
          <mesh>
            <scale>0.001 0.001 0.001</scale>
            <uri>model://interbotix_xsarm_descriptions/meshes/wx200_meshes/wx200_9_gripper_finger.stl</uri>
          </mesh>
        </geometry>
      </visual>
    </link>
    <joint name='left_finger' type='prismatic'>
      <child>wx200/left_finger_link</child>
      <parent>wx200/gripper_link</parent>
      <axis>
        <xyz>0 1 0</xyz>
        <limit>
          <lower>0.015</lower>
          <upper>0.037</upper>
          <effort>5</effort>
          <velocity>1</velocity>
        </limit>
        <dynamics>
          <damping>0</damping>
          <friction>0.1</friction>
          <spring_reference>0</spring_reference>
          <spring_stiffness>0</spring_stiffness>
        </dynamics>
        <use_parent_model_frame>0</use_parent_model_frame>
      </axis>
    </joint>
    <link name='wx200/right_finger_link'>
      <pose frame=''>0.381 0 0.31065 0 -0 0</pose>
      <inertial>
        <pose frame=''>0.013816 0 0 -3.14159 -0 -1.5708</pose>
        <mass>0.016246</mass>
        <inertia>
          <ixx>4.731e-06</ixx>
          <ixy>4.56e-07</ixy>
          <ixz>0</ixz>
          <iyy>1.5506e-06</iyy>
          <iyz>0</iyz>
          <izz>3.7467e-06</izz>
        </inertia>
      </inertial>
      <collision name='wx200/right_finger_link_collision'>
        <pose frame=''>0 -0.005 0 3.14159 -0 3.14159</pose>
        <geometry>
          <mesh>
            <scale>0.001 0.001 0.001</scale>
            <uri>model://interbotix_xsarm_descriptions/meshes/wx200_meshes/wx200_9_gripper_finger.stl</uri>
          </mesh>
        </geometry>
      </collision>
      <visual name='wx200/right_finger_link_visual'>
        <pose frame=''>0 -0.005 0 3.14159 -0 3.14159</pose>
        <geometry>
          <mesh>
            <scale>0.001 0.001 0.001</scale>
            <uri>model://interbotix_xsarm_descriptions/meshes/wx200_meshes/wx200_9_gripper_finger.stl</uri>
          </mesh>
        </geometry>
      </visual>
    </link>
    <joint name='right_finger' type='prismatic'>
      <child>wx200/right_finger_link</child>
      <parent>wx200/gripper_link</parent>
      <axis>
        <xyz>0 1 0</xyz>
        <limit>
          <lower>-0.037</lower>
          <upper>-0.015</upper>
          <effort>5</effort>
          <velocity>1</velocity>
        </limit>
        <dynamics>
          <damping>0</damping>
          <friction>0.1</friction>
          <spring_reference>0</spring_reference>
          <spring_stiffness>0</spring_stiffness>
        </dynamics>
        <use_parent_model_frame>0</use_parent_model_frame>
      </axis>
    </joint>
    <plugin name='gazebo_ros_control' filename='libgazebo_ros_control.so'>
      <robotSimType>gazebo_ros_control/DefaultRobotHWSim</robotSimType>
      <legacyModeNS>1</legacyModeNS>
      <robotNamespace>/wx200/</robotNamespace>
    </plugin>
  </model>
</sdf>
