<?xml version="1.0" ?>
<sdf version="1.5">
  <!-- in this verion the robot arm control is fine but gripper will damping and drone is lock at original position -->
  <model name='iris_aerial_arm'>

    <include>
      <uri>model://iris</uri>
    </include>
    <!-- use include can mount the arm at buttom of drone but controller will have error-->
    <!-- <include> 
      <uri>model://wx250</uri>
      <pose>0 0 0 3.14 0 0</pose>
    </include> -->

    <include>
      <uri>model://depth_camera</uri>
      <pose>0.1 0 0 0 0 0</pose>
    </include>


    <joint name="depth_camera_joint" type="revolute">
      <child>depth_camera::link</child>
      <parent>iris::base_link</parent>
      <axis>
        <xyz>0 0 1</xyz>
        <limit>
          <upper>0</upper>
          <lower>0</lower>
        </limit>
      </axis>
    </joint>

    <!-- <joint name='widowx250_baselink_to_drone_baselink_broken' type='fixed'>
      <child>wx250::wx250/base_link</child>
      <parent>iris::base_link</parent>
      <pose>0 0 -0.05 3.14 0 0</pose>
      <axis>
        <xyz>0 0 1</xyz>
      </axis>
    </joint> -->


    <joint name='widowx250_baselink_to_drone_baselink' type='fixed'>
      <child>wx250/base_link</child>
      <parent>iris::base_link</parent>
      <axis>
        <xyz>0 0 1</xyz>
      </axis>
    </joint>
  

 
    <link name='wx250/base_link'>
      <pose frame=''>0 0 0 0 -0 0</pose>
      <inertial>
        <pose frame=''>-0.038045 0.000614 0.019335 0 -0 1.5708</pose>
        <mass>0.538736</mass>
        <inertia>
          <ixx>0.002115</ixx>
          <ixy>-1.635e-05</ixy>
          <ixz>6.998e-07</ixz>
          <iyy>0.0006921</iyy>
          <iyz>4.642e-05</iyz>
          <izz>0.002524</izz>
        </inertia>
      </inertial>
      <collision name='wx250/base_link_collision'>
        <pose frame=''>0 0 0 0 -0 1.5708</pose>
        <geometry>
          <mesh>
            <scale>0.001 0.001 0.001</scale>
            <uri>/home/argrobotx/robotx-2022/catkin_ws/src/interbotix_arm/interbotix_ros_manipulators/interbotix_ros_xsarms/interbotix_xsarm_descriptions/meshes/wx250_meshes/wx250_1_base.stl</uri>
          </mesh>
        </geometry>
        <surface>
          <contact>
            <ode/>
          </contact>
          <friction>
            <ode/>
            <torsional>
              <ode/>
            </torsional>
          </friction>
          <bounce/>
        </surface>
        <max_contacts>10</max_contacts>
      </collision>
      <visual name='wx250/base_link_visual'>
        <pose frame=''>0 0 0 0 -0 1.5708</pose>
        <geometry>
          <mesh>
            <scale>0.001 0.001 0.001</scale>
            <uri>/home/argrobotx/robotx-2022/catkin_ws/src/interbotix_arm/interbotix_ros_manipulators/interbotix_ros_xsarms/interbotix_xsarm_descriptions/meshes/wx250_meshes/wx250_1_base.stl</uri>
          </mesh>
        </geometry>
        <material>
          <script>
            <name>Custom/Interbotix</name>
            <uri>file://media/materials/scripts/gazebo.material</uri>
          </script>
        </material>
      </visual>
      <gravity>0</gravity>
      <velocity_decay>
        <linear>0.1</linear>
        <angular>0.1</angular>
      </velocity_decay>
      <self_collide>0</self_collide>
      <enable_wind>0</enable_wind>
      <kinematic>0</kinematic>
</link>
    <link name='wx250/shoulder_link'>
      <pose frame=''>0 0 0.072 0 -0 0</pose>
      <inertial>
        <pose frame=''>2.2e-05 4.1e-05 0.006629 0 -0 1.5708</pose>
        <mass>0.480879</mass>
        <inertia>
          <ixx>0.000379</ixx>
          <ixy>2.2e-09</ixy>
          <ixz>-3.561e-07</ixz>
          <iyy>0.0005557</iyy>
          <iyz>1.2245e-06</iyz>
          <izz>0.0005889</izz>
        </inertia>
      </inertial>
      <collision name='wx250/shoulder_link_collision'>
        <pose frame=''>0 0 -0.003 0 -0 1.5708</pose>
        <geometry>
          <mesh>
            <scale>0.001 0.001 0.001</scale>
            <uri>/home/argrobotx/robotx-2022/catkin_ws/src/interbotix_arm/interbotix_ros_manipulators/interbotix_ros_xsarms/interbotix_xsarm_descriptions/meshes/wx250_meshes/wx250_2_shoulder.stl</uri>
          </mesh>
        </geometry>
        <surface>
          <contact>
            <ode/>
          </contact>
          <friction>
            <ode/>
            <torsional>
              <ode/>
            </torsional>
          </friction>
          <bounce/>
        </surface>
        <max_contacts>10</max_contacts>
      </collision>
      <visual name='wx250/shoulder_link_visual'>
        <pose frame=''>0 0 -0.003 0 -0 1.5708</pose>
        <geometry>
          <mesh>
            <scale>0.001 0.001 0.001</scale>
            <uri>/home/argrobotx/robotx-2022/catkin_ws/src/interbotix_arm/interbotix_ros_manipulators/interbotix_ros_xsarms/interbotix_xsarm_descriptions/meshes/wx250_meshes/wx250_2_shoulder.stl</uri>
          </mesh>
        </geometry>
        <material>
          <script>
            <name>Custom/Interbotix</name>
            <uri>file://media/materials/scripts/gazebo.material</uri>
          </script>
        </material>
      </visual>
      <gravity>0</gravity>
      <velocity_decay>
        <linear>0.1</linear>
        <angular>0.1</angular>
      </velocity_decay>
      <self_collide>0</self_collide>
      <enable_wind>0</enable_wind>
      <kinematic>0</kinematic>
    </link>
    <joint name='waist' type='revolute'>
      <child>wx250/shoulder_link</child>
      <parent>wx250/base_link</parent>
      <axis>
        <xyz>0 0 1</xyz>
        <limit>
          <lower>-3.14158</lower>
          <upper>3.14158</upper>
          <effort>10</effort>
          <velocity>3.14159</velocity>
        </limit>
        <dynamics>
          <damping>0</damping>
          <friction>0.1</friction>
          <spring_reference>0</spring_reference>
          <spring_stiffness>0</spring_stiffness>
        </dynamics>
        <use_parent_model_frame>0</use_parent_model_frame>
      </axis>
    </joint>
    <link name='wx250/upper_arm_link'>
      <pose frame=''>0 0 0.11065 0 -0 0</pose>
      <inertial>
        <pose frame=''>0.017161 0 0.191323 0 -0 1.5708</pose>
        <mass>0.430811</mass>
        <inertia>
          <ixx>0.003463</ixx>
          <ixy>-1e-10</ixy>
          <ixz>-2e-10</ixz>
          <iyy>0.003587</iyy>
          <iyz>0.0004272</iyz>
          <izz>0.0004566</izz>
        </inertia>
      </inertial>
      <collision name='wx250/upper_arm_link_collision'>
        <pose frame=''>0 0 0 0 -0 1.5708</pose>
        <geometry>
          <mesh>
            <scale>0.001 0.001 0.001</scale>
            <uri>/home/argrobotx/robotx-2022/catkin_ws/src/interbotix_arm/interbotix_ros_manipulators/interbotix_ros_xsarms/interbotix_xsarm_descriptions/meshes/wx250_meshes/wx250_3_upper_arm.stl</uri>
          </mesh>
        </geometry>
        <surface>
          <contact>
            <ode/>
          </contact>
          <friction>
            <ode/>
            <torsional>
              <ode/>
            </torsional>
          </friction>
          <bounce/>
        </surface>
        <max_contacts>10</max_contacts>
      </collision>
      <visual name='wx250/upper_arm_link_visual'>
        <pose frame=''>0 0 0 0 -0 1.5708</pose>
        <geometry>
          <mesh>
            <scale>0.001 0.001 0.001</scale>
            <uri>/home/argrobotx/robotx-2022/catkin_ws/src/interbotix_arm/interbotix_ros_manipulators/interbotix_ros_xsarms/interbotix_xsarm_descriptions/meshes/wx250_meshes/wx250_3_upper_arm.stl</uri>
          </mesh>
        </geometry>
        <material>
          <script>
            <name>Custom/Interbotix</name>
            <uri>file://media/materials/scripts/gazebo.material</uri>
          </script>
        </material>
      </visual>
      <gravity>0</gravity>
      <velocity_decay>
        <linear>0.1</linear>
        <angular>0.1</angular>
      </velocity_decay>
      <self_collide>0</self_collide>
      <enable_wind>0</enable_wind>
      <kinematic>0</kinematic>
    </link>
    <joint name='shoulder' type='revolute'>
      <child>wx250/upper_arm_link</child>
      <parent>wx250/shoulder_link</parent>
      <axis>
        <xyz>0 1 0</xyz>
        <limit>
          <lower>-1.88496</lower>
          <upper>1.98968</upper>
          <effort>20</effort>
          <velocity>3.14159</velocity>
        </limit>
        <dynamics>
          <damping>0</damping>
          <friction>0.1</friction>
          <spring_reference>0</spring_reference>
          <spring_stiffness>0</spring_stiffness>
        </dynamics>
        <use_parent_model_frame>0</use_parent_model_frame>
      </axis>
    </joint>
    <link name='wx250/forearm_link'>
      <pose frame=''>0.04975 0 0.36065 0 -0 0</pose>
      <inertial>
        <pose frame=''>0.153423 -0.000118 -0.000439 0 -0 1.5708</pose>
        <mass>0.297673</mass>
        <inertia>
          <ixx>0.002176</ixx>
          <ixy>-3.0658e-06</ixy>
          <ixz>0</ixz>
          <iyy>5.757e-05</iyy>
          <iyz>0</iyz>
          <izz>0.002186</izz>
        </inertia>
      </inertial>
      <collision name='wx250/forearm_link_collision'>
        <pose frame=''>0 0 0 0 -0 1.5708</pose>
        <geometry>
          <mesh>
            <scale>0.001 0.001 0.001</scale>
            <uri>/home/argrobotx/robotx-2022/catkin_ws/src/interbotix_arm/interbotix_ros_manipulators/interbotix_ros_xsarms/interbotix_xsarm_descriptions/meshes/wx250_meshes/wx250_4_forearm.stl</uri>
          </mesh>
        </geometry>
        <surface>
          <contact>
            <ode/>
          </contact>
          <friction>
            <ode/>
            <torsional>
              <ode/>
            </torsional>
          </friction>
          <bounce/>
        </surface>
        <max_contacts>10</max_contacts>
      </collision>
      <visual name='wx250/forearm_link_visual'>
        <pose frame=''>0 0 0 0 -0 1.5708</pose>
        <geometry>
          <mesh>
            <scale>0.001 0.001 0.001</scale>
            <uri>/home/argrobotx/robotx-2022/catkin_ws/src/interbotix_arm/interbotix_ros_manipulators/interbotix_ros_xsarms/interbotix_xsarm_descriptions/meshes/wx250_meshes/wx250_4_forearm.stl</uri>
          </mesh>
        </geometry>
        <material>
          <script>
            <name>Custom/Interbotix</name>
            <uri>file://media/materials/scripts/gazebo.material</uri>
          </script>
        </material>
      </visual>
      <gravity>0</gravity>
      <velocity_decay>
        <linear>0.1</linear>
        <angular>0.1</angular>
      </velocity_decay>
      <self_collide>0</self_collide>
      <enable_wind>0</enable_wind>
      <kinematic>0</kinematic>
    </link>
    <joint name='elbow' type='revolute'>
      <child>wx250/forearm_link</child>
      <parent>wx250/upper_arm_link</parent>
      <axis>
        <xyz>0 1 0</xyz>
        <limit>
          <lower>-2.14675</lower>
          <upper>1.6057</upper>
          <effort>15</effort>
          <velocity>3.14159</velocity>
        </limit>
        <dynamics>
          <damping>0</damping>
          <friction>0.1</friction>
          <spring_reference>0</spring_reference>
          <spring_stiffness>0</spring_stiffness>
        </dynamics>
        <use_parent_model_frame>0</use_parent_model_frame>
      </axis>
    </joint>
    <link name='wx250/wrist_link'>
      <pose frame=''>0.29975 0 0.36065 0 -0 0</pose>
      <inertial>
        <pose frame=''>0.04236 -1.1e-05 0.010577 0 -0 1.5708</pose>
        <mass>0.084957</mass>
        <inertia>
          <ixx>3.082e-05</ixx>
          <ixy>1.91e-08</ixy>
          <ixz>2.3e-09</ixz>
          <iyy>2.822e-05</iyy>
          <iyz>2.5481e-06</iyz>
          <izz>3.152e-05</izz>
        </inertia>
      </inertial>
      <collision name='wx250/wrist_link_collision'>
        <pose frame=''>0 0 0 0 -0 1.5708</pose>
        <geometry>
          <mesh>
            <scale>0.001 0.001 0.001</scale>
            <uri>/home/argrobotx/robotx-2022/catkin_ws/src/interbotix_arm/interbotix_ros_manipulators/interbotix_ros_xsarms/interbotix_xsarm_descriptions/meshes/wx250_meshes/wx250_5_wrist.stl</uri>
          </mesh>
        </geometry>
        <surface>
          <contact>
            <ode/>
          </contact>
          <friction>
            <ode/>
            <torsional>
              <ode/>
            </torsional>
          </friction>
          <bounce/>
        </surface>
        <max_contacts>10</max_contacts>
      </collision>
      <visual name='wx250/wrist_link_visual'>
        <pose frame=''>0 0 0 0 -0 1.5708</pose>
        <geometry>
          <mesh>
            <scale>0.001 0.001 0.001</scale>
            <uri>/home/argrobotx/robotx-2022/catkin_ws/src/interbotix_arm/interbotix_ros_manipulators/interbotix_ros_xsarms/interbotix_xsarm_descriptions/meshes/wx250_meshes/wx250_5_wrist.stl</uri>
          </mesh>
        </geometry>
        <material>
          <script>
            <name>Custom/Interbotix</name>
            <uri>file://media/materials/scripts/gazebo.material</uri>
          </script>
        </material>
      </visual>
      <gravity>0</gravity>
      <velocity_decay>
        <linear>0.1</linear>
        <angular>0.1</angular>
      </velocity_decay>
      <self_collide>0</self_collide>
      <enable_wind>0</enable_wind>
      <kinematic>0</kinematic>
    </link>
    <joint name='wrist_angle' type='revolute'>
      <child>wx250/wrist_link</child>
      <parent>wx250/forearm_link</parent>
      <axis>
        <xyz>0 1 0</xyz>
        <limit>
          <lower>-1.74533</lower>
          <upper>2.14675</upper>
          <effort>5</effort>
          <velocity>3.14159</velocity>
        </limit>
        <dynamics>
          <damping>0</damping>
          <friction>0.1</friction>
          <spring_reference>0</spring_reference>
          <spring_stiffness>0</spring_stiffness>
        </dynamics>
        <use_parent_model_frame>0</use_parent_model_frame>
      </axis>
    </joint>
    <link name='wx250/gripper_link'>
      <pose frame=''>0.36475 0 0.36065 0 -0 0</pose>
      <inertial>
        <pose frame=''>0.021631 0 0.01141 0 -0 1.5708</pose>
        <mass>0.072885</mass>
        <inertia>
          <ixx>2.537e-05</ixx>
          <ixy>0</ixy>
          <ixz>0</ixz>
          <iyy>1.836e-05</iyy>
          <iyz>4.34e-07</iyz>
          <izz>1.674e-05</izz>
        </inertia>
      </inertial>
      <collision name='wx250/gripper_link_collision'>
        <pose frame=''>-0.02 0 0 0 -0 1.5708</pose>
        <geometry>
          <mesh>
            <scale>0.001 0.001 0.001</scale>
            <uri>/home/argrobotx/robotx-2022/catkin_ws/src/interbotix_arm/interbotix_ros_manipulators/interbotix_ros_xsarms/interbotix_xsarm_descriptions/meshes/wx250_meshes/wx250_6_gripper.stl</uri>
          </mesh>
        </geometry>
        <surface>
          <contact>
            <ode/>
          </contact>
          <friction>
            <ode/>
            <torsional>
              <ode/>
            </torsional>
          </friction>
          <bounce/>
        </surface>
        <max_contacts>10</max_contacts>
      </collision>
      <visual name='wx250/gripper_link_visual'>
        <pose frame=''>-0.02 0 0 0 -0 1.5708</pose>
        <geometry>
          <mesh>
            <scale>0.001 0.001 0.001</scale>
            <uri>/home/argrobotx/robotx-2022/catkin_ws/src/interbotix_arm/interbotix_ros_manipulators/interbotix_ros_xsarms/interbotix_xsarm_descriptions/meshes/wx250_meshes/wx250_6_gripper.stl</uri>
          </mesh>
        </geometry>
        <material>
          <script>
            <name>Custom/Interbotix</name>
            <uri>file://media/materials/scripts/gazebo.material</uri>
          </script>
        </material>
      </visual>
      <gravity>0</gravity>
      <velocity_decay>
        <linear>0.1</linear>
        <angular>0.1</angular>
      </velocity_decay>
      <self_collide>0</self_collide>
      <enable_wind>0</enable_wind>
      <kinematic>0</kinematic>
    </link>
    <joint name='wrist_rotate' type='revolute'>
      <child>wx250/gripper_link</child>
      <parent>wx250/wrist_link</parent>
      <axis>
        <xyz>1 0 0</xyz>
        <limit>
          <lower>-3.14158</lower>
          <upper>3.14158</upper>
          <effort>1</effort>
          <velocity>3.14159</velocity>
        </limit>
        <dynamics>
          <damping>0</damping>
          <friction>0.1</friction>
          <spring_reference>0</spring_reference>
          <spring_stiffness>0</spring_stiffness>
        </dynamics>
        <use_parent_model_frame>0</use_parent_model_frame>
      </axis>
    </joint>
    <link name='wx250/ee_arm_link'>
      <pose frame=''>0.40775 0 0.36065 0 -0 0</pose>
      <inertial>
        <pose frame=''>0 0 0 0 -0 0</pose>
        <mass>0.001</mass>
        <inertia>
          <ixx>0.001</ixx>
          <ixy>0</ixy>
          <ixz>0</ixz>
          <iyy>0.001</iyy>
          <iyz>0</iyz>
          <izz>0.001</izz>
        </inertia>
      </inertial>
      <self_collide>0</self_collide>
      <enable_wind>0</enable_wind>
      <kinematic>0</kinematic>
    </link>
    <joint name='ee_arm' type='revolute'>
      <child>wx250/ee_arm_link</child>
      <parent>wx250/gripper_link</parent>
      <axis>
        <limit>
          <lower>0</lower>
          <upper>0</upper>
        </limit>
        <dynamics>
          <damping>0</damping>
          <friction>0</friction>
          <spring_reference>0</spring_reference>
          <spring_stiffness>0</spring_stiffness>
        </dynamics>
        <xyz>0 0 1</xyz>
        <use_parent_model_frame>0</use_parent_model_frame>
      </axis>
      <physics>
        <ode>
          <limit>
            <cfm>0</cfm>
            <erp>0.2</erp>
          </limit>
        </ode>
      </physics>
    </joint>
    <link name='wx250/gripper_prop_link'>
      <pose frame=''>0.41325 0 0.36065 0 -0 0</pose>
      <inertial>
        <pose frame=''>0.000846 -2e-06 4.2e-05 0 -0 1.5708</pose>
        <mass>0.00434</mass>
        <inertia>
          <ixx>5.923e-07</ixx>
          <ixy>0</ixy>
          <ixz>3.195e-07</ixz>
          <iyy>1.1156e-06</iyy>
          <iyz>-4e-10</iyz>
          <izz>5.743e-07</izz>
        </inertia>
      </inertial>
      <collision name='wx250/gripper_prop_link_collision'>
        <pose frame=''>-0.0685 0 0 0 -0 1.5708</pose>
        <geometry>
          <mesh>
            <scale>0.001 0.001 0.001</scale>
            <uri>/home/argrobotx/robotx-2022/catkin_ws/src/interbotix_arm/interbotix_ros_manipulators/interbotix_ros_xsarms/interbotix_xsarm_descriptions/meshes/wx250_meshes/wx250_7_gripper_prop.stl</uri>
          </mesh>
        </geometry>
        <surface>
          <contact>
            <ode/>
          </contact>
          <friction>
            <ode/>
            <torsional>
              <ode/>
            </torsional>
          </friction>
          <bounce/>
        </surface>
        <max_contacts>10</max_contacts>
      </collision>
      <visual name='wx250/gripper_prop_link_visual'>
        <pose frame=''>-0.0685 0 0 0 -0 1.5708</pose>
        <geometry>
          <mesh>
            <scale>0.001 0.001 0.001</scale>
            <uri>/home/argrobotx/robotx-2022/catkin_ws/src/interbotix_arm/interbotix_ros_manipulators/interbotix_ros_xsarms/interbotix_xsarm_descriptions/meshes/wx250_meshes/wx250_7_gripper_prop.stl</uri>
          </mesh>
        </geometry>
        <material>
          <script>
            <name>Custom/Interbotix</name>
            <uri>file://media/materials/scripts/gazebo.material</uri>
          </script>
        </material>
      </visual>
      <gravity>0</gravity>
      <velocity_decay>
        <linear>0.1</linear>
        <angular>0.1</angular>
      </velocity_decay>
      <self_collide>0</self_collide>
      <enable_wind>0</enable_wind>
      <kinematic>0</kinematic>
    </link>
    <joint name='gripper' type='revolute'>
      <child>wx250/gripper_prop_link</child>
      <parent>wx250/ee_arm_link</parent>
      <axis>
        <xyz>1 0 0</xyz>
        <limit>
          <lower>-1e+16</lower>
          <upper>1e+16</upper>
        </limit>
        <dynamics>
          <damping>0</damping>
          <friction>0.1</friction>
          <spring_reference>0</spring_reference>
          <spring_stiffness>0</spring_stiffness>
        </dynamics>
        <use_parent_model_frame>0</use_parent_model_frame>
      </axis>
    </joint>
    <link name='wx250/gripper_bar_link'>
      <pose frame=''>0.40775 0 0.36065 0 -0 0</pose>
      <inertial>
        <pose frame=''>0.009687 1e-06 0.004962 0 -0 1.5708</pose>
        <mass>0.034199</mass>
        <inertia>
          <ixx>7.4125e-06</ixx>
          <ixy>-8e-10</ixy>
          <ixz>-6e-10</ixz>
          <iyy>2.843e-05</iyy>
          <iyz>-1.3889e-06</iyz>
          <izz>2.86e-05</izz>
        </inertia>
      </inertial>
      <collision name='wx250/gripper_bar_link_collision'>
        <pose frame=''>-0.063 0 0 0 -0 1.5708</pose>
        <geometry>
          <mesh>
            <scale>0.001 0.001 0.001</scale>
            <uri>/home/argrobotx/robotx-2022/catkin_ws/src/interbotix_arm/interbotix_ros_manipulators/interbotix_ros_xsarms/interbotix_xsarm_descriptions/meshes/wx250_meshes/wx250_8_gripper_bar.stl</uri>
          </mesh>
        </geometry>
        <surface>
          <contact>
            <ode/>
          </contact>
          <friction>
            <ode/>
            <torsional>
              <ode/>
            </torsional>
          </friction>
          <bounce/>
        </surface>
        <max_contacts>10</max_contacts>
      </collision>
      <visual name='wx250/gripper_bar_link_visual'>
        <pose frame=''>-0.063 0 0 0 -0 1.5708</pose>
        <geometry>
          <mesh>
            <scale>0.001 0.001 0.001</scale>
            <uri>/home/argrobotx/robotx-2022/catkin_ws/src/interbotix_arm/interbotix_ros_manipulators/interbotix_ros_xsarms/interbotix_xsarm_descriptions/meshes/wx250_meshes/wx250_8_gripper_bar.stl</uri>
          </mesh>
        </geometry>
        <material>
          <script>
            <name>Custom/Interbotix</name>
            <uri>file://media/materials/scripts/gazebo.material</uri>
          </script>
        </material>
      </visual>
      <gravity>0</gravity>
      <velocity_decay/>
      <self_collide>0</self_collide>
      <enable_wind>0</enable_wind>
      <kinematic>0</kinematic>
    </link>
    <joint name='gripper_bar' type='revolute'>
      <child>wx250/gripper_bar_link</child>
      <parent>wx250/ee_arm_link</parent>
      <axis>
        <limit>
          <lower>0</lower>
          <upper>0</upper>
        </limit>
        <dynamics>
          <damping>0</damping>
          <friction>0</friction>
          <spring_reference>0</spring_reference>
          <spring_stiffness>0</spring_stiffness>
        </dynamics>
        <xyz>0 0 1</xyz>
        <use_parent_model_frame>0</use_parent_model_frame>
      </axis>
      <physics>
        <ode>
          <limit>
            <cfm>0</cfm>
            <erp>0.2</erp>
          </limit>
        </ode>
      </physics>
    </joint>
    <link name='wx250/fingers_link'>
      <pose frame=''>0.43075 0 0.36065 0 -0 0</pose>
      <inertial>
        <pose frame=''>0 0 0 0 -0 0</pose>
        <mass>0.001</mass>
        <inertia>
          <ixx>0.001</ixx>
          <ixy>0</ixy>
          <ixz>0</ixz>
          <iyy>0.001</iyy>
          <iyz>0</iyz>
          <izz>0.001</izz>
        </inertia>
      </inertial>
      <self_collide>0</self_collide>
      <enable_wind>0</enable_wind>
      <kinematic>0</kinematic>
    </link>
    <joint name='ee_bar' type='revolute'>
      <child>wx250/fingers_link</child>
      <parent>wx250/gripper_bar_link</parent>
      <axis>
        <limit>
          <lower>0</lower>
          <upper>0</upper>
        </limit>
        <dynamics>
          <damping>0</damping>
          <friction>0</friction>
          <spring_reference>0</spring_reference>
          <spring_stiffness>0</spring_stiffness>
        </dynamics>
        <xyz>0 0 1</xyz>
        <use_parent_model_frame>0</use_parent_model_frame>
      </axis>
      <physics>
        <ode>
          <limit>
            <cfm>0</cfm>
            <erp>0.2</erp>
          </limit>
        </ode>
      </physics>
    </joint>
    <link name='wx250/ee_gripper_link'>
      <pose frame=''>0.458325 0 0.36065 0 -0 0</pose>
      <inertial>
        <pose frame=''>0 0 0 0 -0 0</pose>
        <mass>0.001</mass>
        <inertia>
          <ixx>0.001</ixx>
          <ixy>0</ixy>
          <ixz>0</ixz>
          <iyy>0.001</iyy>
          <iyz>0</iyz>
          <izz>0.001</izz>
        </inertia>
      </inertial>
      <self_collide>0</self_collide>
      <enable_wind>0</enable_wind>
      <kinematic>0</kinematic>
    </link>
    <joint name='ee_gripper' type='revolute'>
      <child>wx250/ee_gripper_link</child>
      <parent>wx250/fingers_link</parent>
      <axis>
        <limit>
          <lower>0</lower>
          <upper>0</upper>
        </limit>
        <dynamics>
          <damping>0</damping>
          <friction>0</friction>
          <spring_reference>0</spring_reference>
          <spring_stiffness>0</spring_stiffness>
        </dynamics>
        <xyz>0 0 1</xyz>
        <use_parent_model_frame>0</use_parent_model_frame>
      </axis>
      <physics>
        <ode>
          <limit>
            <cfm>0</cfm>
            <erp>0.2</erp>
          </limit>
        </ode>
      </physics>
    </joint>
    <link name='wx250/left_finger_link'>
      <pose frame=''>0.43075 0 0.36065 0 -0 0</pose>
      <inertial>
        <pose frame=''>0.013816 0 0 0 -0 -1.5708</pose>
        <mass>0.016246</mass>
        <inertia>
          <ixx>4.731e-06</ixx>
          <ixy>-4.56e-07</ixy>
          <ixz>0</ixz>
          <iyy>1.5506e-06</iyy>
          <iyz>0</iyz>
          <izz>3.7467e-06</izz>
        </inertia>
      </inertial>
      <collision name='wx250/left_finger_link_collision'>
        <pose frame=''>0 0.005 0 0 -0 3.14159</pose>
        <geometry>
          <mesh>
            <scale>0.001 0.001 0.001</scale>
            <uri>/home/argrobotx/robotx-2022/catkin_ws/src/interbotix_arm/interbotix_ros_manipulators/interbotix_ros_xsarms/interbotix_xsarm_descriptions/meshes/wx250_meshes/wx250_9_gripper_finger.stl</uri>
          </mesh>
        </geometry>
        <surface>
          <contact>
            <ode/>
          </contact>
          <friction>
            <ode/>
            <torsional>
              <ode/>
            </torsional>
          </friction>
          <bounce/>
        </surface>
        <max_contacts>10</max_contacts>
      </collision>
      <visual name='wx250/left_finger_link_visual'>
        <pose frame=''>0 0.005 0 0 -0 3.14159</pose>
        <geometry>
          <mesh>
            <scale>0.001 0.001 0.001</scale>
            <uri>/home/argrobotx/robotx-2022/catkin_ws/src/interbotix_arm/interbotix_ros_manipulators/interbotix_ros_xsarms/interbotix_xsarm_descriptions/meshes/wx250_meshes/wx250_9_gripper_finger.stl</uri>
          </mesh>
        </geometry>
        <material>
          <script>
            <name>Custom/Interbotix</name>
            <uri>file://media/materials/scripts/gazebo.material</uri>
          </script>
        </material>
      </visual>
      <gravity>0</gravity>
      <velocity_decay>
        <linear>0.1</linear>
        <angular>0.1</angular>
      </velocity_decay>
      <self_collide>0</self_collide>
      <enable_wind>0</enable_wind>
      <kinematic>0</kinematic>
    </link>
    <joint name='left_finger' type='prismatic'>
      <child>wx250/left_finger_link</child>
      <parent>wx250/fingers_link</parent>
      <axis>
        <xyz>0 1 0</xyz>
        <limit>
          <lower>0.015</lower>
          <upper>0.037</upper>
          <effort>5</effort>
          <velocity>1</velocity>
        </limit>
        <dynamics>
          <damping>0</damping>
          <friction>0.1</friction>
          <spring_reference>0</spring_reference>
          <spring_stiffness>0</spring_stiffness>
        </dynamics>
        <use_parent_model_frame>0</use_parent_model_frame>
      </axis>
    </joint>
    <link name='wx250/right_finger_link'>
      <pose frame=''>0.43075 0 0.36065 0 -0 0</pose>
      <inertial>
        <pose frame=''>0.013816 0 0 -3.14159 -0 -1.5708</pose>
        <mass>0.016246</mass>
        <inertia>
          <ixx>4.731e-06</ixx>
          <ixy>4.56e-07</ixy>
          <ixz>0</ixz>
          <iyy>1.5506e-06</iyy>
          <iyz>0</iyz>
          <izz>3.7467e-06</izz>
        </inertia>
      </inertial>
      <collision name='wx250/right_finger_link_collision'>
        <pose frame=''>0 -0.005 0 3.14159 -0 3.14159</pose>
        <geometry>
          <mesh>
            <scale>0.001 0.001 0.001</scale>
            <uri>/home/argrobotx/robotx-2022/catkin_ws/src/interbotix_arm/interbotix_ros_manipulators/interbotix_ros_xsarms/interbotix_xsarm_descriptions/meshes/wx250_meshes/wx250_9_gripper_finger.stl</uri>
          </mesh>
        </geometry>
        <surface>
          <contact>
            <ode/>
          </contact>
          <friction>
            <ode/>
            <torsional>
              <ode/>
            </torsional>
          </friction>
          <bounce/>
        </surface>
        <max_contacts>10</max_contacts>
      </collision>
      <visual name='wx250/right_finger_link_visual'>
        <pose frame=''>0 -0.005 0 3.14159 -0 3.14159</pose>
        <geometry>
          <mesh>
            <scale>0.001 0.001 0.001</scale>
            <uri>/home/argrobotx/robotx-2022/catkin_ws/src/interbotix_arm/interbotix_ros_manipulators/interbotix_ros_xsarms/interbotix_xsarm_descriptions/meshes/wx250_meshes/wx250_9_gripper_finger.stl</uri>
          </mesh>
        </geometry>
        <material>
          <script>
            <name>Custom/Interbotix</name>
            <uri>file://media/materials/scripts/gazebo.material</uri>
          </script>
        </material>
      </visual>
      <gravity>0</gravity>
      <velocity_decay>
        <linear>0.1</linear>
        <angular>0.1</angular>
      </velocity_decay>
      <self_collide>0</self_collide>
      <enable_wind>0</enable_wind>
      <kinematic>0</kinematic>
    </link>
    <joint name='right_finger' type='prismatic'>
      <child>wx250/right_finger_link</child>
      <parent>wx250/fingers_link</parent>
      <axis>
        <xyz>0 1 0</xyz>
        <limit>
          <lower>-0.037</lower>
          <upper>-0.015</upper>
          <effort>5</effort>
          <velocity>1</velocity>
        </limit>
        <dynamics>
          <damping>0</damping>
          <friction>0.1</friction>
          <spring_reference>0</spring_reference>
          <spring_stiffness>0</spring_stiffness>
        </dynamics>
        <use_parent_model_frame>0</use_parent_model_frame>
      </axis>
    </joint>
    <static>0</static>
    <plugin name='gazebo_ros_control' filename='libgazebo_ros_control.so'>
      <robotSimType>gazebo_ros_control/DefaultRobotHWSim</robotSimType>
      <legacyModeNS>1</legacyModeNS>
      <robotNamespace>/wx250/</robotNamespace>
    </plugin>
    <pose frame=''>0 0 0 0 -0 0</pose>
  </model>
</sdf> 




<!-- For cgo3 arm model only robot arm model can't control movement and gripper
<?xml version="1.0" ?>
<sdf version="1.5">
  <model name='iris_aerial_arm'>

    <include>
      <uri>model://iris</uri>
    </include>

    <include>
      <uri>model://cgo3_arm</uri>
    </include>

    <include>
      <uri>model://depth_camera</uri>
      <pose>0.1 0 0 0 0 0</pose>
    </include>


    <joint name="depth_camera_joint" type="revolute">
      <child>depth_camera::link</child>
      <parent>iris::base_link</parent>
      <axis>
        <xyz>0 0 1</xyz>
        <limit>
          <upper>0</upper>
          <lower>0</lower>
        </limit>
      </axis>
    </joint>


    <joint name='cgo3_mount_joint' type='revolute'>
      <child>cgo3_arm::cgo3_mount_link</child>
      <parent>iris::base_link</parent>
      <pose>0 0 0 0 0 0</pose>
      <axis>
        <xyz>0 0 1</xyz>
        <limit>
          <lower>0</lower>
          <upper>0</upper>
          <effort>100</effort>
          <velocity>-1</velocity>
        </limit>
        <dynamics>
          <damping>1</damping>
        </dynamics>
        <use_parent_model_frame>1</use_parent_model_frame>
      </axis>
      <physics>
        <ode>
          <implicit_spring_damper>1</implicit_spring_damper>
        </ode>
      </physics>
    </joint>
  </model>
</sdf> -->
